Workbook

Sheet Plan
A1: enabled | B1: date | C1: weekday | D1: title | E1: session_type | F1: planned_duration_min | G1: planned_km | H1: planned_hr_min | I1: planned_hr_max | J1: planned_notes | K1: planned_fuel_to_bring | L1: planned_fuel_timing | M1: event_mode_override | N1: start_time_override | O1: end_time_override | P1: status | Q1: actual_km | R1: actual_duration_min | S1: actual_avg_hr | T1: actual_max_hr | U1: actual_avg_pace | V1: actual_rpe | W1: actual_notes | X1: actual_fuel_notes | Y1: feedback_summary | Z1: calendar_event_id | AA1: event_last_synced_at | AB1: calendar_title_snapshot
A2: TRUE | B2: 46111 | C2: Monday | D2: Easy / prep | E2: run | F2: 40 | G2: 6 | H2: 125 | I2: 140 | J2: Easy day. If Tuesday long run becomes impossible, move the long run here and reduce Tuesday. | K2: Optional water only | P2: planned
A3: TRUE | B3: 46112 | C3: Tuesday | D3: Long run | E3: run | F3: 75 | G3: 12 | H3: 135 | I3: 145 | J3: Preferred long-run day. | K3: 1 banana + water | L3: 35-40 min: half banana; 60-70 min: finish banana | P3: planned
A4: TRUE | B4: 46113 | C4: Wednesday | D4: Recovery / optional jog | E4: recovery | H4: 120 | I4: 135 | J4: Skip if legs feel beat up. | K4: Optional water only | P4: planned
A5: TRUE | B5: 46114 | C5: Thursday | D5: Football | E5: football | F5: 120 | H5: 150 | I5: 175 | J5: Football replaces speed / interval work. | K5: Water; optional banana 60-90 min before | L5: Before: small carb snack; during: water only | P5: planned
A6: TRUE | B6: 46115 | C6: Friday | D6: Fasting / rest | E6: rest | J6: No hard training before 17:00. Usually rest or easy walk only. | K6: None | P6: planned
A7: TRUE | B7: 46116 | C7: Saturday | D7: Medium Z2 run | E7: run | F7: 50 | G7: 9 | H7: 135 | I7: 145 | J7: Controlled aerobic run. | K7: Optional water only | P7: planned
A8: TRUE | B8: 46117 | C8: Sunday | D8: Bike hills | E8: bike | F8: 75 | H8: 130 | I8: 145 | J8: Climb-focused bike ride; moderate, not maximal. | K8: Water + banana OR dates/raisins | L8: Sip every 15-20 min; small carbs at 40-50 min if needed | P8: planned
A9: TRUE | B9: 46118 | C9: Monday | D9: Easy / prep | E9: run | F9: 35 | G9: 5 | H9: 125 | I9: 140 | J9: Easy day. If Tuesday long run becomes impossible, move the long run here and reduce Tuesday. | K9: Optional water only | P9: planned
A10: TRUE | B10: 46119 | C10: Tuesday | D10: Long run | E10: run | F10: 85 | G10: 14 | H10: 135 | I10: 145 | J10: Preferred long-run day. | K10: 1 banana + 2-3 dates/raisins + water | L10: 35 min: banana; 65-70 min: dates/raisins | P10: planned
A11: TRUE | B11: 46120 | C11: Wednesday | D11: Recovery / optional jog | E11: recovery | F11: 30 | G11: 4 | H11: 120 | I11: 135 | J11: Skip if legs feel beat up. | K11: Optional water only | P11: planned
A12: TRUE | B12: 46121 | C12: Thursday | D12: Football | E12: football | F12: 120 | H12: 150 | I12: 175 | J12: Football replaces speed / interval work. | K12: Water; optional banana 60-90 min before | L12: Before: small carb snack; during: water only | P12: planned
A13: TRUE | B13: 46122 | C13: Friday | D13: Fasting / rest | E13: rest | J13: No hard training before 17:00. Usually rest or easy walk only. | K13: None | P13: planned
A14: TRUE | B14: 46123 | C14: Saturday | D14: Medium Z2 run | E14: run | F14: 55 | G14: 10 | H14: 135 | I14: 145 | J14: Controlled aerobic run. | K14: Optional water only | P14: planned
A15: TRUE | B15: 46124 | C15: Sunday | D15: Bike hills | E15: bike | F15: 75 | H15: 130 | I15: 145 | J15: Climb-focused bike ride; moderate, not maximal. | K15: Water + banana OR dates/raisins | L15: Sip every 15-20 min; small carbs at 40-50 min if needed | P15: planned
A16: TRUE | B16: 46125 | C16: Monday | D16: Easy / prep | E16: run | F16: 40 | G16: 6 | H16: 125 | I16: 140 | J16: Easy day. If Tuesday long run becomes impossible, move the long run here and reduce Tuesday. | K16: Optional water only | P16: planned
A17: TRUE | B17: 46126 | C17: Tuesday | D17: Long run | E17: run | F17: 95 | G17: 16 | H17: 135 | I17: 145 | J17: Preferred long-run day. | K17: 1 banana + 2-3 dates/raisins + water | L17: 35 min: banana; 65-70 min: dates/raisins | P17: planned
A18: TRUE | B18: 46127 | C18: Wednesday | D18: Recovery / optional jog | E18: recovery | H18: 120 | I18: 135 | J18: Skip if legs feel beat up. | K18: Optional water only | P18: planned
A19: TRUE | B19: 46128 | C19: Thursday | D19: Football | E19: football | F19: 120 | H19: 150 | I19: 175 | J19: Football replaces speed / interval work. | K19: Water; optional banana 60-90 min before | L19: Before: small carb snack; during: water only | P19: planned
A20: TRUE | B20: 46129 | C20: Friday | D20: Fasting / rest | E20: rest | J20: No hard training before 17:00. Usually rest or easy walk only. | K20: None | P20: planned
A21: TRUE | B21: 46130 | C21: Saturday | D21: Medium Z2 run | E21: run | F21: 55 | G21: 10 | H21: 135 | I21: 145 | J21: Controlled aerobic run. | K21: Optional water only | P21: planned
A22: TRUE | B22: 46131 | C22: Sunday | D22: Bike hills | E22: bike | F22: 80 | H22: 130 | I22: 145 | J22: Climb-focused bike ride; moderate, not maximal. | K22: Water + banana OR dates/raisins | L22: Sip every 15-20 min; small carbs at 40-50 min if needed | P22: planned
A23: TRUE | B23: 46132 | C23: Monday | D23: Easy / prep | E23: run | F23: 35 | G23: 6 | H23: 125 | I23: 140 | J23: Easy day. If Tuesday long run becomes impossible, move the long run here and reduce Tuesday. | K23: Optional water only | P23: planned
A24: TRUE | B24: 46133 | C24: Tuesday | D24: Long run (deload) | E24: run | F24: 75 | G24: 12 | H24: 135 | I24: 145 | J24: Preferred long-run day. | K24: 1 banana + water | L24: 35-40 min: half banana; 60-70 min: finish banana | P24: planned
A25: TRUE | B25: 46134 | C25: Wednesday | D25: Recovery / optional jog | E25: recovery | F25: 30 | G25: 4 | H25: 120 | I25: 135 | J25: Skip if legs feel beat up. | K25: Optional water only | P25: planned
A26: TRUE | B26: 46135 | C26: Thursday | D26: Football | E26: football | F26: 120 | H26: 150 | I26: 175 | J26: Football replaces speed / interval work. | K26: Water; optional banana 60-90 min before | L26: Before: small carb snack; during: water only | P26: planned
A27: TRUE | B27: 46136 | C27: Friday | D27: Fasting / rest | E27: rest | J27: No hard training before 17:00. Usually rest or easy walk only. | K27: None | P27: planned
A28: TRUE | B28: 46137 | C28: Saturday | D28: Easy Z2 run | E28: run | F28: 45 | G28: 8 | H28: 125 | I28: 140 | J28: Controlled aerobic run. | K28: Optional water only | P28: planned
A29: TRUE | B29: 46138 | C29: Sunday | D29: Bike easy | E29: bike | F29: 60 | H29: 130 | I29: 145 | J29: Climb-focused bike ride; moderate, not maximal. | K29: Water | L29: Sip as needed | P29: planned
A30: TRUE | B30: 46139 | C30: Monday | D30: Easy / prep | E30: run | F30: 40 | G30: 6 | H30: 125 | I30: 140 | J30: Easy day. If Tuesday long run becomes impossible, move the long run here and reduce Tuesday. | K30: Optional water only | P30: planned
A31: TRUE | B31: 46140 | C31: Tuesday | D31: Long run | E31: run | F31: 110 | G31: 18 | H31: 135 | I31: 145 | J31: Preferred long-run day. | K31: 1 banana + dates/raisins + small honey sandwich + water | L31: 30-35 min: banana; 60-70 min: dates; 90 min: honey bite | P31: planned
A32: TRUE | B32: 46141 | C32: Wednesday | D32: Recovery / optional jog | E32: recovery | H32: 120 | I32: 135 | J32: Skip if legs feel beat up. | K32: Optional water only | P32: planned
A33: TRUE | B33: 46142 | C33: Thursday | D33: Football | E33: football | F33: 120 | H33: 150 | I33: 175 | J33: Football replaces speed / interval work. | K33: Water; optional banana 60-90 min before | L33: Before: small carb snack; during: water only | P33: planned
A34: TRUE | B34: 46143 | C34: Friday | D34: Fasting / rest | E34: rest | J34: No hard training before 17:00. Usually rest or easy walk only. | K34: None | P34: planned
A35: TRUE | B35: 46144 | C35: Saturday | D35: Medium Z2 run | E35: run | F35: 60 | G35: 11 | H35: 135 | I35: 145 | J35: Controlled aerobic run. | K35: Optional water; banana if you start underfueled | L35: Water as needed; optional banana around 40-45 min | P35: planned
A36: TRUE | B36: 46145 | C36: Sunday | D36: Bike hills | E36: bike | F36: 80 | H36: 130 | I36: 145 | J36: Climb-focused bike ride; moderate, not maximal. | K36: Water + banana OR dates/raisins | L36: Sip every 15-20 min; small carbs at 40-50 min if needed | P36: planned
A37: TRUE | B37: 46146 | C37: Monday | D37: Easy / prep | E37: run | F37: 35 | G37: 6 | H37: 125 | I37: 140 | J37: Easy day. If Tuesday long run becomes impossible, move the long run here and reduce Tuesday. | K37: Optional water only | P37: planned
A38: TRUE | B38: 46147 | C38: Tuesday | D38: Long run | E38: run | F38: 120 | G38: 20 | H38: 135 | I38: 145 | J38: Preferred long-run day. | K38: 1 banana + small honey sandwich + dates/raisins + water | L38: 30 min: banana; 60 min: honey; 90 min: dates/raisins | P38: planned
A39: TRUE | B39: 46148 | C39: Wednesday | D39: Recovery / optional jog | E39: recovery | F39: 30 | G39: 4 | H39: 120 | I39: 135 | J39: Skip if legs feel beat up. | K39: Optional water only | P39: planned
A40: TRUE | B40: 46149 | C40: Thursday | D40: Football | E40: football | F40: 120 | H40: 150 | I40: 175 | J40: Football replaces speed / interval work. | K40: Water; optional banana 60-90 min before | L40: Before: small carb snack; during: water only | P40: planned
...

Sheet Schedule
A1: weekday | B1: event_mode | C1: start_time | D1: end_time | E1: notes
A2: Monday | B2: ALL_DAY | E2: Use ALL_DAY by default; set TIMED if you want this day on the grid.
A3: Tuesday | B3: ALL_DAY | E3: Preferred long-run day.
A4: Wednesday | B4: ALL_DAY | E4: Recovery day.
A5: Thursday | B5: TIMED | C5: 20:00 | D5: 22:00 | E5: Football default slot.
A6: Friday | B6: ALL_DAY | E6: Fasting / rest.
A7: Saturday | B7: ALL_DAY | E7: Medium/easy run.
A8: Sunday | B8: ALL_DAY | E8: Bike day.

Sheet Settings
A1: key | B1: value | C1: notes
A2: calendar_id | B2: primary | C2: Google Calendar ID; "primary" usually works
A3: title_prefix | B3: TRAIN | C3: Prefix used in event titles
A4: delete_prefix | B4: TRAIN | C4: deletePrefixedEvents deletes titles beginning with this prefix
A5: use_schedule | B5: TRUE | C5: If TRUE, Schedule sheet controls ALL_DAY vs TIMED unless row override exists
A6: default_event_mode | B6: ALL_DAY | C6: ALL_DAY or TIMED
A7: feedback_block_start | B7: [FEEDBACK] | C7: Do not change unless you also change the parser
A8: feedback_block_end | B8: [/FEEDBACK] | C8: Do not change unless you also change the parser
A9: feedback_from_calendar_enabled | B9: TRUE | C9: Set TRUE to allow importing feedback from calendar

Sheet Logs
A1: timestamp | B1: level | C1: function | D1: row_number | E1: message

Sheet README
A1: This workbook is the source of truth for the training plan.
A2: Calendar event text is intentionally simple.
A3: Edit only the lines inside [FEEDBACK] ... [/FEEDBACK].
A4: New: fueling is included in the Plan sheet and in each calendar event.
A5: Plan columns added:
A6: planned_fuel_to_bring
A7: planned_fuel_timing
A8: actual_fuel_notes
A10: Accepted feedback examples:
A11: status=done
A12: km=12
A13: duration_min=75
... A21: status=skipped

Sheet Feedback
A1: date | B1: title | C1: status | D1: planned_km | E1: actual_km | F1: planned_duration_min | G1: actual_duration_min | H1: planned_hr | I1: actual_avg_hr | J1: actual_avg_pace | K1: planned_fuel_to_bring | L1: planned_fuel_timing | M1: actual_fuel_notes | N1: actual_rpe | O1: actual_notes
A2: =Plan!B2 | B2: =Plan!D2 | C2: =Plan!P2 | D2: =Plan!G2 | E2: =Plan!Q2 | F2: =Plan!F2 | G2: =Plan!R2 | H2: =IF(AND(Plan!H2="",Plan!I2=""),"",Plan!H2&"-"&Plan!I2) | I2: =Plan!S2 | J2: =Plan!U2 | K2: =Plan!K2 | L2: =Plan!L2 | M2: =Plan!X2 | N2: =Plan!V2 | O2: =Plan!W2
A3: =Plan!B3 | B3: =Plan!D3 | C3: =Plan!P3 | D3: =Plan!G3 | E3: =Plan!Q3 | F3: =Plan!F3 | G3: =Plan!R3 | H3: =IF(AND(Plan!H3="",Plan!I3=""),"",Plan!H3&"-"&Plan!I3) | I3: =Plan!S3 | J3: =Plan!U3 | K3: =Plan!K3 | L3: =Plan!L3 | M3: =Plan!X3 | N3: =Plan!V3 | O3: =Plan!W3
A4: =Plan!B4 | B4: =Plan!D4 | C4: =Plan!P4 | D4: =Plan!G4 | E4: =Plan!Q4 | F4: =Plan!F4 | G4: =Plan!R4 | H4: =IF(AND(Plan!H4="",Plan!I4=""),"",Plan!H4&"-"&Plan!I4) | I4: =Plan!S4 | J4: =Plan!U4 | K4: =Plan!K4 | L4: =Plan!L4 | M4: =Plan!X4 | N4: =Plan!V4 | O4: =Plan!W4
A5: =Plan!B5 | B5: =Plan!D5 | C5: =Plan!P5 | D5: =Plan!G5 | E5: =Plan!Q5 | F5: =Plan!F5 | G5: =Plan!R5 | H5: =IF(AND(Plan!H5="",Plan!I5=""),"",Plan!H5&"-"&Plan!I5) | I5: =Plan!S5 | J5: =Plan!U5 | K5: =Plan!K5 | L5: =Plan!L5 | M5: =Plan!X5 | N5: =Plan!V5 | O5: =Plan!W5
A6: =Plan!B6 | B6: =Plan!D6 | C6: =Plan!P6 | D6: =Plan!G6 | E6: =Plan!Q6 | F6: =Plan!F6 | G6: =Plan!R6 | H6: =IF(AND(Plan!H6="",Plan!I6=""),"",Plan!H6&"-"&Plan!I6) | I6: =Plan!S6 | J6: =Plan!U6 | K6: =Plan!K6 | L6: =Plan!L6 | M6: =Plan!X6 | N6: =Plan!V6 | O6: =Plan!W6
A7: =Plan!B7 | B7: =Plan!D7 | C7: =Plan!P7 | D7: =Plan!G7 | E7: =Plan!Q7 | F7: =Plan!F7 | G7: =Plan!R7 | H7: =IF(AND(Plan!H7="",Plan!I7=""),"",Plan!H7&"-"&Plan!I7) | I7: =Plan!S7 | J7: =Plan!U7 | K7: =Plan!K7 | L7: =Plan!L7 | M7: =Plan!X7 | N7: =Plan!V7 | O7: =Plan!W7
A8: =Plan!B8 | B8: =Plan!D8 | C8: =Plan!P8 | D8: =Plan!G8 | E8: =Plan!Q8 | F8: =Plan!F8 | G8: =Plan!R8 | H8: =IF(AND(Plan!H8="",Plan!I8=""),"",Plan!H8&"-"&Plan!I8) | I8: =Plan!S8 | J8: =Plan!U8 | K8: =Plan!K8 | L8: =Plan!L8 | M8: =Plan!X8 | N8: =Plan!V8 | O8: =Plan!W8
A9: =Plan!B9 | B9: =Plan!D9 | C9: =Plan!P9 | D9: =Plan!G9 | E9: =Plan!Q9 | F9: =Plan!F9 | G9: =Plan!R9 | H9: =IF(AND(Plan!H9="",Plan!I9=""),"",Plan!H9&"-"&Plan!I9) | I9: =Plan!S9 | J9: =Plan!U9 | K9: =Plan!K9 | L9: =Plan!L9 | M9: =Plan!X9 | N9: =Plan!V9 | O9: =Plan!W9
A10: =Plan!B10 | B10: =Plan!D10 | C10: =Plan!P10 | D10: =Plan!G10 | E10: =Plan!Q10 | F10: =Plan!F10 | G10: =Plan!R10 | H10: =IF(AND(Plan!H10="",Plan!I10=""),"",Plan!H10&"-"&Plan!I10) | I10: =Plan!S10 | J10: =Plan!U10 | K10: =Plan!K10 | L10: =Plan!L10 | M10: =Plan!X10 | N10: =Plan!V10 | O10: =Plan!W10
A11: =Plan!B11 | B11: =Plan!D11 | C11: =Plan!P11 | D11: =Plan!G11 | E11: =Plan!Q11 | F11: =Plan!F11 | G11: =Plan!R11 | H11: =IF(AND(Plan!H11="",Plan!I11=""),"",Plan!H11&"-"&Plan!I11) | I11: =Plan!S11 | J11: =Plan!U11 | K11: =Plan!K11 | L11: =Plan!L11 | M11: =Plan!X11 | N11: =Plan!V11 | O11: =Plan!W11
A12: =Plan!B12 | B12: =Plan!D12 | C12: =Plan!P12 | D12: =Plan!G12 | E12: =Plan!Q12 | F12: =Plan!F12 | G12: =Plan!R12 | H12: =IF(AND(Plan!H12="",Plan!I12=""),"",Plan!H12&"-"&Plan!I12) | I12: =Plan!S12 | J12: =Plan!U12 | K12: =Plan!K12 | L12: =Plan!L12 | M12: =Plan!X12 | N12: =Plan!V12 | O12: =Plan!W12
A13: =Plan!B13 | B13: =Plan!D13 | C13: =Plan!P13 | D13: =Plan!G13 | E13: =Plan!Q13 | F13: =Plan!F13 | G13: =Plan!R13 | H13: =IF(AND(Plan!H13="",Plan!I13=""),"",Plan!H13&"-"&Plan!I13) | I13: =Plan!S13 | J13: =Plan!U13 | K13: =Plan!K13 | L13: =Plan!L13 | M13: =Plan!X13 | N13: =Plan!V13 | O13: =Plan!W13
... A57: =Plan!B57 | B57: =Plan!D57 | C57: =Plan!P57 | D57: =Plan!G57 | E57: =Plan!Q57 | F57: =Plan!F57 | G57: =Plan!R57 | H57: =IF(AND(Plan!H57="",Plan!I57=""),"",Plan!H57&"-"&Plan!I57) | I57: =Plan!S57 | J57: =Plan!U57 | K57: =Plan!K57 | L57: =Plan!L57 | M57: =Plan!X57 | N57: =Plan!V57 | O57: =Plan!W57
